<?xml version="1.0" encoding="utf-8"?>
<!-- This URDF was automatically created by SolidWorks to URDF Exporter! Originally created by Stephen Brawner (brawner@gmail.com) 
     Commit Version: 1.6.0-1-g15f4949  Build Version: 1.6.7594.29634
     For more information, please see http://wiki.ros.org/sw_urdf_exporter -->
<robot
  name="mirobot_urdf">
  <link
    name="base_link">
    <inertial>
      <origin
        xyz="0 -1.73472347597681E-18 0.0295630938396228"
        rpy="0 0 0" />
      <mass
        value="0.830460463625083" />
      <inertia
        ixx="0.00122515441017336"
        ixy="5.06212586523845E-39"
        ixz="-9.27088146783836E-21"
        iyy="0.00122515441017336"
        iyz="-2.14545897338503E-21"
        izz="0.00181346064064253" />
    </inertial>
    <visual>
      <origin
        xyz="0 0 0"
        rpy="0 0 0" />
      <geometry>
        <mesh
          filename="package://mirobot_urdf/meshes/base_link.STL" />
      </geometry>
      <material
        name="">
        <color
          rgba="0.47843137254902 0.47843137254902 0.47843137254902 1" />
      </material>
    </visual>
    <collision>
      <origin
        xyz="0 0 0"
        rpy="0 0 0" />
      <geometry>
        <mesh
          filename="package://mirobot_urdf/meshes/base_link_collision.STL" />
      </geometry>
    </collision>
  </link>
  <link
    name="link1">
    <inertial>
      <origin
        xyz="0.0139204674030074 0.000175675755774408 0.0278204776833535"
        rpy="0 0 0" />
      <mass
        value="0.100783545378023" />
      <inertia
        ixx="3.54957422514902E-05"
        ixy="-2.36772178333946E-07"
        ixz="-1.29966775792725E-05"
        iyy="6.20674035359101E-05"
        iyz="-1.81648408097106E-07"
        izz="4.09412060690147E-05" />
    </inertial>
    <visual>
      <origin
        xyz="0 0 0"
        rpy="0 0 0" />
      <geometry>
        <mesh
          filename="package://mirobot_urdf/meshes/link1.STL" />
      </geometry>
      <material
        name="">
        <color
          rgba="0.792156862745098 0.819607843137255 0.933333333333333 1" />
      </material>
    </visual>
    <collision>
      <origin
        xyz="0 0 0"
        rpy="0 0 0" />
      <geometry>
        <mesh
          filename="package://mirobot_urdf/meshes/link1_collision.STL" />
      </geometry>
    </collision>
  </link>
  <joint
    name="Joint1"
    type="revolute">
    <origin
      xyz="0 0 0.08907"
      rpy="0 0 0" />
    <parent
      link="base_link" />
    <child
      link="link1" />
    <axis
      xyz="0 0 1" />
    <limit
      lower="-1.919"
      upper="2.792"
      effort="10"
      velocity="1.484" />
  </joint>
  <link
    name="link2">
    <inertial>
      <origin
        xyz="-0.000285886360290435 -0.0166552740240192 0.049757717069139"
        rpy="0 0 0" />
      <mass
        value="0.132170739177703" />
      <inertia
        ixx="0.000214469616122437"
        ixy="4.08289814520086E-10"
        ixz="6.39020671260653E-07"
        iyy="0.000225756619197558"
        iyz="4.14008992711757E-08"
        izz="2.33050461983938E-05" />
    </inertial>
    <visual>
      <origin
        xyz="0 0 0"
        rpy="0 0 0" />
      <geometry>
        <mesh
          filename="package://mirobot_urdf/meshes/link2.STL" />
      </geometry>
      <material
        name="">
        <color
          rgba="1 0.6 0.247058823529412 1" />
      </material>
    </visual>
    <collision>
      <origin
        xyz="0 0 0"
        rpy="0 0 0" />
      <geometry>
        <mesh
          filename="package://mirobot_urdf/meshes/link2_collision.STL" />
      </geometry>
    </collision>
  </link>
  <joint
    name="Joint2"
    type="revolute">
    <origin
      xyz="0.026689 -0.01 0.037919"
      rpy="0 0 0" />
    <parent
      link="link1" />
    <child
      link="link2" />
    <axis
      xyz="0 1 0" />
    <limit
      lower="-0.611"
      upper="1.222"
      effort="10"
      velocity="1.047" />
  </joint>
  <link
    name="link3">
    <inertial>
      <origin
        xyz="0.0158954987739833 0.0218157412359182 0.00468222502163174"
        rpy="0 0 0" />
      <mass
        value="0.0999858744473074" />
      <inertia
        ixx="3.50335003907214E-05"
        ixy="8.27653396401829E-07"
        ixz="-2.38306289339889E-05"
        iyy="0.000119385641846118"
        iyz="2.43801748853214E-07"
        izz="0.000122716522763449" />
    </inertial>
    <visual>
      <origin
        xyz="0 0 0"
        rpy="0 0 0" />
      <geometry>
        <mesh
          filename="package://mirobot_urdf/meshes/link3.STL" />
      </geometry>
      <material
        name="">
        <color
          rgba="0.792156862745098 0.819607843137255 0.933333333333333 1" />
      </material>
    </visual>
    <collision>
      <origin
        xyz="0 0 0"
        rpy="0 0 0" />
      <geometry>
        <mesh
          filename="package://mirobot_urdf/meshes/link3_collision.STL" />
      </geometry>
    </collision>
  </link>
  <joint
    name="Joint3"
    type="revolute">
    <origin
      xyz="-0.00052147 0 0.10356"
      rpy="0 0 0" />
    <parent
      link="link2" />
    <child
      link="link3" />
    <axis
      xyz="0 1 0" />
    <limit
      lower="-2.094"
      upper="1.047"
      effort="10"
      velocity="1.134" />
  </joint>
  <link
    name="link4">
    <inertial>
      <origin
        xyz="0.0397448300249128 -3.52690543263534E-07 8.51158590914336E-07"
        rpy="0 0 0" />
      <mass
        value="0.0455776802932786" />
      <inertia
        ixx="1.02362105187764E-05"
        ixy="-3.09042973810874E-10"
        ixz="4.93005005983085E-10"
        iyy="1.74414096073689E-05"
        iyz="-3.59690099161977E-11"
        izz="2.34678990160725E-05" />
    </inertial>
    <visual>
      <origin
        xyz="0 0 0"
        rpy="0 0 0" />
      <geometry>
        <mesh
          filename="package://mirobot_urdf/meshes/link4.STL" />
      </geometry>
      <material
        name="">
        <color
          rgba="1 0.6 0.247058823529412 1" />
      </material>
    </visual>
    <collision>
      <origin
        xyz="0 0 0"
        rpy="0 0 0" />
      <geometry>
        <mesh
          filename="package://mirobot_urdf/meshes/link4_collision.STL" />
      </geometry>
    </collision>
  </link>
  <joint
    name="Joint4"
    type="revolute">
    <origin
      xyz="0.11123 0.021295 0.019995"
      rpy="0 0 0" />
    <parent
      link="link3" />
    <child
      link="link4" />
    <axis
      xyz="-1 0 0" />
    <limit
      lower="-3.142"
      upper="3.142"
      effort="10"
      velocity="3.49" />
  </joint>
  <link
    name="link5">
    <inertial>
      <origin
        xyz="1.36127220606852E-13 0.00629500118952138 0.00755281484467515"
        rpy="0 0 0" />
      <mass
        value="0.0143827723830484" />
      <inertia
        ixx="1.94302435347813E-06"
        ixy="2.82362999964957E-14"
        ixz="3.73150978210105E-17"
        iyy="1.83052685569596E-06"
        iyz="1.73296816140335E-11"
        izz="1.09303987751683E-06" />
    </inertial>
    <visual>
      <origin
        xyz="0 0 0"
        rpy="0 0 0" />
      <geometry>
        <mesh
          filename="package://mirobot_urdf/meshes/link5.STL" />
      </geometry>
      <material
        name="">
        <color
          rgba="0.792156862745098 0.819607843137255 0.933333333333333 1" />
      </material>
    </visual>
    <collision>
      <origin
        xyz="0 0 0"
        rpy="0 0 0" />
      <geometry>
        <mesh
          filename="package://mirobot_urdf/meshes/link5_collision.STL" />
      </geometry>
    </collision>
  </link>
  <joint
    name="Joint5"
    type="revolute">
    <origin
      xyz="0.05775 0.006295 0"
      rpy="3.1416 0 0" />
    <parent
      link="link4" />
    <child
      link="link5" />
    <axis
      xyz="0 -1 0" />
    <limit
      lower="-3.49"
      upper="0.523"
      effort="10"
      velocity="3490" />
  </joint>
  <link
    name="link6">
    <inertial>
      <origin
        xyz="0.0204857453646831 -3.59449001698792E-07 -0.0175088771378945"
        rpy="0 0 0" />
      <mass
        value="0.0381323787621174" />
      <inertia
        ixx="3.5467614209665E-06"
        ixy="1.29728264109457E-11"
        ixz="1.8330055985815E-06"
        iyy="2.62395180142313E-05"
        iyz="-8.9373167517803E-11"
        izz="2.59682850543536E-05" />
    </inertial>
    <visual>
      <origin
        xyz="0 0 0"
        rpy="0 0 0" />
      <geometry>
        <mesh
          filename="package://mirobot_urdf/meshes/link6.STL" />
      </geometry>
      <material
        name="">
        <color
          rgba="1 1 1 1" />
      </material>
    </visual>
    <collision>
      <origin
        xyz="0 0 0"
        rpy="3.14159 0 3.14159" />
      <geometry>
        <mesh
          filename="package://mirobot_urdf/meshes/link6_collision.STL" />
      </geometry>
    </collision>
  </link>
  <joint
    name="Joint6"
    type="revolute">
    <origin
      xyz="0 0.0062949 0.019304"
      rpy="3.1416 0 0" />
    <parent
      link="link5" />
    <child
      link="link6" />
    <axis
      xyz="0 2.7322E-05 1" />
    <limit
      lower="-6.283"
      upper="6.283"
      effort="10"
      velocity="7.854" />
  </joint>
  <link
    name="link61">
    <inertial>
      <origin
        xyz="0.0049999999981338 1.36611643736934E-07 -0.106942148760331"
        rpy="0 0 0" />
      <mass
        value="0.112186666358773" />
      <inertia
        ixx="1.05678287095848E-05"
        ixy="4.71171791974171E-22"
        ixz="-4.5278500442868E-22"
        iyy="1.05678287095848E-05"
        iyz="1.77213333993801E-21"
        izz="1.55382009766395E-05" />
    </inertial>
    <visual>
      <origin
        xyz="0 0 0"
        rpy="0 0 0" />
      <geometry>
        <mesh
          filename="package://mirobot_urdf/meshes/link61.STL" />
      </geometry>
      <material
        name="">
        <color
          rgba="1 1 1 1" />
      </material>
    </visual>
    <collision>
      <origin
        xyz="0 0 0"
        rpy="0 0 0" />
      <geometry>
        <mesh
          filename="package://mirobot_urdf/meshes/link61.STL" />
      </geometry>
    </collision>
  </link>
  <joint
    name="Joint61"
    type="fixed">
    <origin
      xyz="-0.046 0 -0.016"
      rpy="3.1416 1.5708 0" />
    <parent
      link="link6" />
    <child
      link="link61" />
    <axis
      xyz="0 0 0" />
  </joint>
</robot>
