<?xml version="1.0" encoding="utf-8"?>
<!-- This URDF was automatically created by SolidWorks to URDF Exporter! Originally created by Stephen Brawner (brawner@gmail.com) 
     Commit Version: 1.6.0-1-g15f4949  Build Version: 1.6.7594.29634
     For more information, please see http://wiki.ros.org/sw_urdf_exporter -->
<robot
  name="mirobot_urdf">
  <link
    name="base_link">
    <inertial>
      <origin
        xyz="0 -1.7347E-18 0.029563"
        rpy="0 0 0" />
      <mass
        value="0.83046" />
      <inertia
        ixx="0.0012252"
        ixy="0"
        ixz="-9.9845E-21"
        iyy="0.0012252"
        iyz="0"
        izz="0.0018135" />
    </inertial>
    <visual>
      <origin
        xyz="0 0 0"
        rpy="0 0 0" />
      <geometry>
        <mesh
          filename="package://mirobot_urdf/meshes/base_link.STL" />
      </geometry>
      <material
        name="">
        <color
          rgba="0.47843 0.47843 0.47843 1" />
      </material>
    </visual>
    <collision>
      <origin
        xyz="0 0 0"
        rpy="0 0 0" />
      <geometry>
        <mesh
          filename="package://mirobot_urdf/meshes/base_link_collision.STL" />
      </geometry>
    </collision>
  </link>
  <link
    name="link1">
    <inertial>
      <origin
        xyz="0.01392 0.00017568 0.02782"
        rpy="0 0 0" />
      <mass
        value="0.10078" />
      <inertia
        ixx="3.5496E-05"
        ixy="-2.3677E-07"
        ixz="-1.2997E-05"
        iyy="6.2067E-05"
        iyz="-1.8165E-07"
        izz="4.0941E-05" />
    </inertial>
    <visual>
      <origin
        xyz="0 0 0"
        rpy="0 0 0" />
      <geometry>
        <mesh
          filename="package://mirobot_urdf/meshes/link1.STL" />
      </geometry>
      <material
        name="">
        <color
          rgba="0.79216 0.81961 0.93333 1" />
      </material>
    </visual>
    <collision>
      <origin
        xyz="0 0 0"
        rpy="0 0 0" />
      <geometry>
        <mesh
          filename="package://mirobot_urdf/meshes/link1_collision.STL" />
      </geometry>
    </collision>
  </link>
  <joint
    name="Joint1"
    type="revolute">
    <origin
      xyz="0 0 0.08907"
      rpy="0 0 0" />
    <parent
      link="base_link" />
    <child
      link="link1" />
    <axis
      xyz="0 0 1" />
    <limit
      lower="-1.919"
      upper="2.792"
      effort="10"
      velocity="1.484" />
  </joint>
  <link
    name="link2">
    <inertial>
      <origin
        xyz="-0.000285886360290435 -0.0166552740240192 0.049757717069139"
        rpy="0 0 0" />
      <mass
        value="0.132170739177703" />
      <inertia
        ixx="0.000214469616122437"
        ixy="4.0828981452006E-10"
        ixz="6.39020671260653E-07"
        iyy="0.000225756619197558"
        iyz="4.14008992711782E-08"
        izz="2.33050461983938E-05" />
    </inertial>
    <visual>
      <origin
        xyz="0 0 0"
        rpy="0 0 0" />
      <geometry>
        <mesh
          filename="package://mirobot_urdf/meshes/link2.STL" />
      </geometry>
      <material
        name="">
        <color
          rgba="1 0.6 0.247058823529412 1" />
      </material>
    </visual>
    <collision>
      <origin
        xyz="0 0 0"
        rpy="0 0 0" />
      <geometry>
        <mesh
          filename="package://mirobot_urdf/meshes/link2_collision.STL" />
      </geometry>
    </collision>
  </link>
  <joint
    name="Joint2"
    type="revolute">
    <origin
      xyz="0.026689 -0.01 0.037919"
      rpy="0 0 0" />
    <parent
      link="link1" />
    <child
      link="link2" />
    <axis
      xyz="0 1 0" />
    <limit
      lower="-0.611"
      upper="1.222"
      effort="10"
      velocity="1.047" />
  </joint>
  <link
    name="link3">
    <inertial>
      <origin
        xyz="0.0158954987739833 0.0218157412359182 0.00468222502163174"
        rpy="0 0 0" />
      <mass
        value="0.0999858744473074" />
      <inertia
        ixx="3.50335003907214E-05"
        ixy="8.27653396401826E-07"
        ixz="-2.38306289339889E-05"
        iyy="0.000119385641846118"
        iyz="2.43801748853215E-07"
        izz="0.000122716522763449" />
    </inertial>
    <visual>
      <origin
        xyz="0 0 0"
        rpy="0 0 0" />
      <geometry>
        <mesh
          filename="package://mirobot_urdf/meshes/link3.STL" />
      </geometry>
      <material
        name="">
        <color
          rgba="0.792156862745098 0.819607843137255 0.933333333333333 1" />
      </material>
    </visual>
    <collision>
      <origin
        xyz="0 0 0"
        rpy="0 0 0" />
      <geometry>
        <mesh
          filename="package://mirobot_urdf/meshes/link3_collision.STL" />
      </geometry>
    </collision>
  </link>
  <joint
    name="Joint3"
    type="revolute">
    <origin
      xyz="-0.00052147 0 0.10356"
      rpy="0 0 0" />
    <parent
      link="link2" />
    <child
      link="link3" />
    <axis
      xyz="0 1 0" />
    <limit
      lower="-2.094"
      upper="1.047"
      effort="10"
      velocity="1.134" />
  </joint>
  <link
    name="link4">
    <inertial>
      <origin
        xyz="0.0397448300249128 -3.52690543263534E-07 8.51158590914336E-07"
        rpy="0 0 0" />
      <mass
        value="0.0455776802932786" />
      <inertia
        ixx="1.02362105187764E-05"
        ixy="-3.090429738105E-10"
        ixz="4.93005005982154E-10"
        iyy="1.74414096073689E-05"
        iyz="-3.59690099161495E-11"
        izz="2.34678990160725E-05" />
    </inertial>
    <visual>
      <origin
        xyz="0 0 0"
        rpy="0 0 0" />
      <geometry>
        <mesh
          filename="package://mirobot_urdf/meshes/link4.STL" />
      </geometry>
      <material
        name="">
        <color
          rgba="1 0.6 0.247058823529412 1" />
      </material>
    </visual>
    <collision>
      <origin
        xyz="0 0 0"
        rpy="0 0 0" />
      <geometry>
        <mesh
          filename="package://mirobot_urdf/meshes/link4_collision.STL" />
      </geometry>
    </collision>
  </link>
  <joint
    name="Joint4"
    type="revolute">
    <origin
      xyz="0.11123 0.021295 0.019995"
      rpy="0 0 0" />
    <parent
      link="link3" />
    <child
      link="link4" />
    <axis
      xyz="-1 0 0" />
    <limit
      lower="-3.142"
      upper="3.142"
      effort="10"
      velocity="3.49" />
  </joint>
  <link
    name="link5">
    <inertial>
      <origin
        xyz="1.3613E-13 0.006295 0.0075528"
        rpy="0 0 0" />
      <mass
        value="0.014383" />
      <inertia
        ixx="1.943E-06"
        ixy="2.8236E-14"
        ixz="3.7315E-17"
        iyy="1.8305E-06"
        iyz="1.733E-11"
        izz="1.093E-06" />
    </inertial>
    <visual>
      <origin
        xyz="0 0 0"
        rpy="0 0 0" />
      <geometry>
        <mesh
          filename="package://mirobot_urdf/meshes/link5.STL" />
      </geometry>
      <material
        name="">
        <color
          rgba="0.79216 0.81961 0.93333 1" />
      </material>
    </visual>
    <collision>
      <origin
        xyz="0 0 0"
        rpy="0 0 0" />
      <geometry>
        <mesh
          filename="package://mirobot_urdf/meshes/link5_collision.STL" />
      </geometry>
    </collision>
  </link>
  <joint
    name="Joint5"
    type="revolute">
    <origin
      xyz="0.05775 0.006295 0"
      rpy="3.1416 0 0" />
    <parent
      link="link4" />
    <child
      link="link5" />
    <axis
      xyz="0 -1 0" />
    <limit
      lower="-3.49"
      upper="0.523"
      effort="10"
      velocity="3490" />
  </joint>
  <link
    name="link6">
    <inertial>
      <origin
        xyz="-0.020486 -3.5945E-07 0.017509"
        rpy="0 0 0" />
      <mass
        value="0.038132" />
      <inertia
        ixx="3.5468E-06"
        ixy="-1.2973E-11"
        ixz="1.833E-06"
        iyy="2.624E-05"
        iyz="8.9373E-11"
        izz="2.5968E-05" />
    </inertial>
    <visual>
      <origin
        xyz="0 0 0"
        rpy="0 0 0" />
      <geometry>
        <mesh
          filename="package://mirobot_urdf/meshes/link6.STL" />
      </geometry>
      <material
        name="">
        <color
          rgba="1 1 1 1" />
      </material>
    </visual>
    <collision>
      <origin
        xyz="0 0 0"
        rpy="0 0 0" />
      <geometry>
        <mesh
          filename="package://mirobot_urdf/meshes/link6_collision.STL" />
      </geometry>
    </collision>
  </link>
  <joint
    name="Joint6"
    type="revolute">
    <origin
      xyz="0 0.0062949 0.019304"
      rpy="0 0 3.1416" />
    <parent
      link="link5" />
    <child
      link="link6" />
    <axis
      xyz="0 2.7322E-05 -1" />
    <limit
      lower="-6.283"
      upper="6.283"
      effort="10"
      velocity="7.854" />
  </joint>
  <link
    name="link61">
    <inertial>
      <origin
        xyz="0.005 1.3661E-07 -0.10694"
        rpy="0 0 0" />
      <mass
        value="0.11219" />
      <inertia
        ixx="1.0568E-05"
        ixy="9.5028E-22"
        ixz="-6.3416E-22"
        iyy="1.0568E-05"
        iyz="1.1226E-21"
        izz="1.5538E-05" />
    </inertial>
    <visual>
      <origin
        xyz="0 0 0"
        rpy="0 0 0" />
      <geometry>
        <mesh
          filename="package://mirobot_urdf/meshes/link61.STL" />
      </geometry>
      <material
        name="">
        <color
          rgba="1 1 1 1" />
      </material>
    </visual>
    <collision>
      <origin
        xyz="0 0 0"
        rpy="0 0 0" />
      <geometry>
        <mesh
          filename="package://mirobot_urdf/meshes/link61.STL" />
      </geometry>
    </collision>
  </link>
  <joint
    name="Joint61"
    type="fixed">
    <origin
      xyz="0.046 0 0.027"
      rpy="0 1.5708 0" />
    <parent
      link="link6" />
    <child
      link="link61" />
    <axis
      xyz="0 0 0" />
  </joint>
</robot>
